processes			| 1
seed				| 19
lambda				| 0.01
upper bound			| 4096
context switch time	| 4
alpha				| 0.5
time slice			| 64


------------------------------
time 0ms: Simulator started for FCFS [Q: empty]
time 33ms: Process A arrived; added to ready queue [Q: A]
time 35ms: Process Astarted using the CPU for 207ms burst [Q: empty]
time 242ms: Process A completed a CPU burst; 14 bursts to go [Q: empty]
time 242ms: Process A switching out of CPU; will block on I/O until time 582ms [Q: empty]
time 582ms: Process A completed I/O; added to ready queue [Q: A]
time 586ms: Process Astarted using the CPU for 105ms burst [Q: empty]
time 691ms: Process A completed a CPU burst; 13 bursts to go [Q: empty]
time 691ms: Process A switching out of CPU; will block on I/O until time 811ms [Q: empty]
time 811ms: Process A completed I/O; added to ready queue [Q: A]
time 815ms: Process Astarted using the CPU for 226ms burst [Q: empty]
time 1041ms: Process A completed a CPU burst; 12 bursts to go [Q: empty]
time 1041ms: Process A switching out of CPU; will block on I/O until time 2761ms [Q: empty]
time 2761ms: Process A completed I/O; added to ready queue [Q: A]
time 2765ms: Process Astarted using the CPU for 64ms burst [Q: empty]
time 2829ms: Process A completed a CPU burst; 11 bursts to go [Q: empty]
time 2829ms: Process A switching out of CPU; will block on I/O until time 3439ms [Q: empty]
time 3439ms: Process A completed I/O; added to ready queue [Q: A]
time 3443ms: Process Astarted using the CPU for 44ms burst [Q: empty]
time 3487ms: Process A completed a CPU burst; 10 bursts to go [Q: empty]
time 3487ms: Process A switching out of CPU; will block on I/O until time 4137ms [Q: empty]
time 4137ms: Process A completed I/O; added to ready queue [Q: A]
time 4141ms: Process Astarted using the CPU for 110ms burst [Q: empty]
time 4251ms: Process A completed a CPU burst; 9 bursts to go [Q: empty]
time 4251ms: Process A switching out of CPU; will block on I/O until time 4881ms [Q: empty]
time 4881ms: Process A completed I/O; added to ready queue [Q: A]
time 4885ms: Process Astarted using the CPU for 4ms burst [Q: empty]
time 4889ms: Process A completed a CPU burst; 8 bursts to go [Q: empty]
time 4889ms: Process A switching out of CPU; will block on I/O until time 4959ms [Q: empty]
time 4959ms: Process A completed I/O; added to ready queue [Q: A]
time 4963ms: Process Astarted using the CPU for 11ms burst [Q: empty]
time 4974ms: Process A completed a CPU burst; 7 bursts to go [Q: empty]
time 4974ms: Process A switching out of CPU; will block on I/O until time 5264ms [Q: empty]
time 5264ms: Process A completed I/O; added to ready queue [Q: A]
time 5268ms: Process Astarted using the CPU for 82ms burst [Q: empty]
time 5350ms: Process A completed a CPU burst; 6 bursts to go [Q: empty]
time 5350ms: Process A switching out of CPU; will block on I/O until time 7100ms [Q: empty]
time 7100ms: Process A completed I/O; added to ready queue [Q: A]
time 7104ms: Process Astarted using the CPU for 49ms burst [Q: empty]
time 7153ms: Process A completed a CPU burst; 5 bursts to go [Q: empty]
time 7153ms: Process A switching out of CPU; will block on I/O until time 10733ms [Q: empty]
time 10733ms: Process A completed I/O; added to ready queue [Q: A]
time 10737ms: Process Astarted using the CPU for 117ms burst [Q: empty]
time 10854ms: Process A completed a CPU burst; 4 bursts to go [Q: empty]
time 10854ms: Process A switching out of CPU; will block on I/O until time 11014ms [Q: empty]
time 11014ms: Process A completed I/O; added to ready queue [Q: A]
time 11018ms: Process Astarted using the CPU for 73ms burst [Q: empty]
time 11091ms: Process A completed a CPU burst; 3 bursts to go [Q: empty]
time 11091ms: Process A switching out of CPU; will block on I/O until time 12691ms [Q: empty]
time 12691ms: Process A completed I/O; added to ready queue [Q: A]
time 12695ms: Process Astarted using the CPU for 117ms burst [Q: empty]
time 12812ms: Process A completed a CPU burst; 2 bursts to go [Q: empty]
time 12812ms: Process A switching out of CPU; will block on I/O until time 13882ms [Q: empty]
time 13882ms: Process A completed I/O; added to ready queue [Q: A]
time 13886ms: Process Astarted using the CPU for 69ms burst [Q: empty]
time 13955ms: Process A completed a CPU burst; 1 bursts to go [Q: empty]
time 13955ms: Process A switching out of CPU; will block on I/O until time 13955ms [Q: empty]
time 13955ms: Process A completed I/O; added to ready queue [Q: A]
total time: 13957
